Workbook

Sheet Selected_Config
A1: Final ARIMA / SARIMA configuration by material and forecast horizon | B1: Final ARIMA / SARIMA configuration by material and forecast horizon | C1: Final ARIMA / SARIMA configuration by material and forecast horizon | D1: Final ARIMA / SARIMA configuration by material and forecast horizon | E1: Final ARIMA / SARIMA configuration by material and forecast horizon | F1: Final ARIMA / SARIMA configuration by material and forecast horizon | G1: Final ARIMA / SARIMA configuration by material and forecast horizon | H1: Final ARIMA / SARIMA configuration by material and forecast horizon | I1: Final ARIMA / SARIMA configuration by material and forecast horizon | J1: Final ARIMA / SARIMA configuration by material and forecast horizon | K1: Final ARIMA / SARIMA configuration by material and forecast horizon | L1: Final ARIMA / SARIMA configuration by material and forecast horizon | M1: Final ARIMA / SARIMA configuration by material and forecast horizon
A2: Applied thresholds: relative sMAPE gap ≤ 1.0%; median within-method ΔAICc ≤ 2.0. Engine: statsmodels SARIMAX for both ARIMA and SARIMA.
A3: 52 configurations selected: 51 meet both thresholds; 1 fallback is flagged for Material 9, Horizon 22.
A4: material | B4: horizon | C4: registry_model | D4: engine | E4: candidate | F4: order | G4: seasonal_order | H4: mean_smape | I4: relative_smape_gap | J4: median_delta_aicc | K4: complexity_pqPQ | L4: decision_status | M4: selection_reason
A5: 1 | B5: 10 | C5: arima | D5: SARIMAX | E5: sarima_112_100_5 | F5: (1, 1, 2) | G5: (1, 0, 0, 5) | H5: 0.10202197 | I5: 0 | J5: 0 | K5: 4 | L5: joint_acceptable | M5: Both thresholds met; simplest eligible AR/MA structure selected.
A6: 2 | B6: 10 | C6: arima | D6: SARIMAX | E6: arima_111 | F6: (1, 1, 1) | G6: (0, 0, 0, 0) | H6: 0.13610648 | I6: 0 | J6: 0 | K6: 2 | L6: joint_acceptable | M6: Both thresholds met; simplest eligible AR/MA structure selected.
A7: 3 | B7: 10 | C7: arima | D7: SARIMAX | E7: arima_111 | F7: (1, 1, 1) | G7: (0, 0, 0, 0) | H7: 0.15576663 | I7: 0.0030479005 | J7: 1.417 | K7: 2 | L7: joint_acceptable | M7: Both thresholds met; simplest eligible AR/MA structure selected.
A8: 4 | B8: 10 | C8: arima | D8: SARIMAX | E8: arima_011 | F8: (0, 1, 1) | G8: (0, 0, 0, 0) | H8: 0.15993546 | I8: 0 | J8: 0 | K8: 1 | L8: joint_acceptable | M8: Both thresholds met; simplest eligible AR/MA structure selected.
A9: 5 | B9: 10 | C9: arima | D9: SARIMAX | E9: arima_102 | F9: (1, 0, 2) | G9: (0, 0, 0, 0) | H9: 0.10261218 | I9: 0.0093115191 | J9: 0 | K9: 3 | L9: joint_acceptable | M9: Both thresholds met; simplest eligible AR/MA structure selected.
A10: 6 | B10: 10 | C10: arima | D10: SARIMAX | E10: arima_011 | F10: (0, 1, 1) | G10: (0, 0, 0, 0) | H10: 0.12748419 | I10: 0.0035440936 | J10: 0 | K10: 1 | L10: joint_acceptable | M10: Both thresholds met; simplest eligible AR/MA structure selected.
A11: 7 | B11: 10 | C11: arima | D11: SARIMAX | E11: arima_011 | F11: (0, 1, 1) | G11: (0, 0, 0, 0) | H11: 0.2481418 | I11: 0.0004329501 | J11: 1.048 | K11: 1 | L11: joint_acceptable | M11: Both thresholds met; simplest eligible AR/MA structure selected.
A12: 8 | B12: 10 | C12: arima | D12: SARIMAX | E12: arima_011 | F12: (0, 1, 1) | G12: (0, 0, 0, 0) | H12: 0.17889177 | I12: 0 | J12: 0.509 | K12: 1 | L12: joint_acceptable | M12: Both thresholds met; simplest eligible AR/MA structure selected.
A13: 9 | B13: 10 | C13: arima | D13: SARIMAX | E13: arima_211 | F13: (2, 1, 1) | G13: (0, 0, 0, 0) | H13: 0.17985229 | I13: 0 | J13: 0 | K13: 3 | L13: joint_acceptable | M13: Both thresholds met; simplest eligible AR/MA structure selected.
A14: 10 | B14: 10 | C14: arima | D14: SARIMAX | E14: arima_012 | F14: (0, 1, 2) | G14: (0, 0, 0, 0) | H14: 0.11002943 | I14: 0 | J14: 0 | K14: 2 | L14: joint_acceptable | M14: Both thresholds met; simplest eligible AR/MA structure selected.
A15: 11 | B15: 10 | C15: arima | D15: SARIMAX | E15: sarima_112_001_5 | F15: (1, 1, 2) | G15: (0, 0, 1, 5) | H15: 0.40762161 | I15: 0 | J15: 0 | K15: 4 | L15: joint_acceptable | M15: Both thresholds met; simplest eligible AR/MA structure selected.
A16: 12 | B16: 10 | C16: arima | D16: SARIMAX | E16: arima_500 | F16: (5, 0, 0) | G16: (0, 0, 0, 0) | H16: 1.0783377 | I16: 0 | J16: 0 | K16: 5 | L16: joint_acceptable | M16: Both thresholds met; simplest eligible AR/MA structure selected.
... A56: 13 | B56: 132 | C56: arima | D56: SARIMAX | E56: sarima_113_002_5 | F56: (1, 1, 3) | G56: (0, 0, 2, 5) | H56: 1.8343843 | I56: 0.00061734085 | J56: 0 | K56: 6 | L56: joint_acceptable | M56: Both thresholds met; simplest eligible AR/MA structure selected.

Sheet Combined_Evidence
A1: AICc + rolling-CV sMAPE evidence by material, horizon, and candidate | B1: AICc + rolling-CV sMAPE evidence by material, horizon, and candidate | C1: AICc + rolling-CV sMAPE evidence by material, horizon, and candidate | D1: AICc + rolling-CV sMAPE evidence by material, horizon, and candidate | E1: AICc + rolling-CV sMAPE evidence by material, horizon, and candidate | F1: AICc + rolling-CV sMAPE evidence by material, horizon, and candidate | G1: AICc + rolling-CV sMAPE evidence by material, horizon, and candidate | H1: AICc + rolling-CV sMAPE evidence by material, horizon, and candidate | I1: AICc + rolling-CV sMAPE evidence by material, horizon, and candidate | J1: AICc + rolling-CV sMAPE evidence by material, horizon, and candidate | K1: AICc + rolling-CV sMAPE evidence by material, horizon, and candidate | L1: AICc + rolling-CV sMAPE evidence by material, horizon, and candidate | M1: AICc + rolling-CV sMAPE evidence by material, horizon, and candidate | N1: AICc + rolling-CV sMAPE evidence by material, horizon, and candidate | O1: AICc + rolling-CV sMAPE evidence by material, horizon, and candidate | P1: AICc + rolling-CV sMAPE evidence by material, horizon, and candidate | Q1: AICc + rolling-CV sMAPE evidence by material, horizon, and candidate | R1: AICc + rolling-CV sMAPE evidence by material, horizon, and candidate | S1: AICc + rolling-CV sMAPE evidence by material, horizon, and candidate | T1: AICc + rolling-CV sMAPE evidence by material, horizon, and candidate | U1: AICc + rolling-CV sMAPE evidence by material, horizon, and candidate | V1: AICc + rolling-CV sMAPE evidence by material, horizon, and candidate | W1: AICc + rolling-CV sMAPE evidence by material, horizon, and candidate | X1: AICc + rolling-CV sMAPE evidence by material, horizon, and candidate | Y1: AICc + rolling-CV sMAPE evidence by material, horizon, and candidate | Z1: AICc + rolling-CV sMAPE evidence by material, horizon, and candidate | AA1: AICc + rolling-CV sMAPE evidence by material, horizon, and candidate
A2: Green selected rows form the final 52-entry configuration. AICc columns remain method-specific; sMAPE columns share the same CV design.
A4: material | B4: horizon | C4: candidate | D4: order | E4: seasonal_order | F4: model_type | G4: mean_smape | H4: sum_smape | I4: folds | J4: best_smape | K4: relative_smape_gap | L4: smape_acceptable | M4: linear_aicc | N4: linear_delta | O4: pchip_aicc | P4: pchip_delta | Q4: spline_aicc | R4: spline_delta | S4: aicc_evidence_count | T4: median_delta_aicc | U4: max_delta_aicc | V4: aicc_acceptable | W4: joint_acceptable | X4: complexity_pqPQ | Y4: selected | Z4: decision_status | AA4: selection_reason
A5: 1 | B5: 10 | C5: sarima_112_100_5 | D5: (1, 1, 2) | E5: (1, 0, 0, 5) | F5: SARIMA | G5: 0.10202197 | H5: 2.7545931 | I5: 27 | J5: =_xludf.MINIFS($G$5:$G$168,$A$5:$A$168,A5,$B$5:$B$168,B5) -> #NAME? | K5: =IF(J5=0,0,(G5-J5)/J5) -> #NAME? | L5: =K5<=Rules!$B$5 -> #NAME? | M5: -3844.78 | N5: 0 | O5: -3836.968 | P5: 0 | Q5: -3858.851 | R5: 0 | S5: 3 | T5: 0 | U5: 0 | V5: =T5<=Rules!$B$4 -> TRUE | W5: =AND(L5,V5) -> #NAME? | X5: 4 | Y5: TRUE | Z5: joint_acceptable | AA5: Both thresholds met; simplest eligible AR/MA structure selected.
A6: 1 | B6: 10 | C6: arima_112 | D6: (1, 1, 2) | E6: (0, 0, 0, 0) | F6: ARIMA | G6: 0.10521149 | H6: 2.8407101 | I6: 27 | J6: =_xludf.MINIFS($G$5:$G$168,$A$5:$A$168,A6,$B$5:$B$168,B6) -> #NAME? | K6: =IF(J6=0,0,(G6-J6)/J6) -> #NAME? | L6: =K6<=Rules!$B$5 -> #NAME? | M6: -3842.27 | N6: 2.51 | O6: -3836.025 | P6: 0.943 | Q6: -3857.196 | R6: 1.655 | S6: 3 | T6: 1.655 | U6: 2.51 | V6: =T6<=Rules!$B$4 -> TRUE | W6: =AND(L6,V6) -> #NAME? | X6: 3 | Y6: FALSE | Z6: not_selected | AA6: Outside the final eligible set.
A7: 2 | B7: 10 | C7: arima_111 | D7: (1, 1, 1) | E7: (0, 0, 0, 0) | F7: ARIMA | G7: 0.13610648 | H7: 3.6748751 | I7: 27 | J7: =_xludf.MINIFS($G$5:$G$168,$A$5:$A$168,A7,$B$5:$B$168,B7) -> #NAME? | K7: =IF(J7=0,0,(G7-J7)/J7) -> #NAME? | L7: =K7<=Rules!$B$5 -> #NAME? | M7: -4426.001 | N7: 0 | O7: -4425.005 | P7: 0 | Q7: -4432.271 | R7: 0 | S7: 3 | T7: 0 | U7: 0 | V7: =T7<=Rules!$B$4 -> TRUE | W7: =AND(L7,V7) -> #NAME? | X7: 2 | Y7: TRUE | Z7: joint_acceptable | AA7: Both thresholds met; simplest eligible AR/MA structure selected.
A8: 3 | B8: 10 | C8: sarima_111_002_5 | D8: (1, 1, 1) | E8: (0, 0, 2, 5) | F8: SARIMA | G8: 0.15529331 | H8: 4.1929193 | I8: 27 | J8: =_xludf.MINIFS($G$5:$G$168,$A$5:$A$168,A8,$B$5:$B$168,B8) -> #NAME? | K8: =IF(J8=0,0,(G8-J8)/J8) -> #NAME? | L8: =K8<=Rules!$B$5 -> #NAME? | M8: -4495.978 | N8: 0 | O8: -4480.862 | P8: 0 | Q8: -4530.517 | R8: 0 | S8: 3 | T8: 0 | U8: 0 | V8: =T8<=Rules!$B$4 -> TRUE | W8: =AND(L8,V8) -> #NAME? | X8: 4 | Y8: FALSE | Z8: not_selected | AA8: Outside the final eligible set.
A9: 3 | B9: 10 | C9: arima_111 | D9: (1, 1, 1) | E9: (0, 0, 0, 0) | F9: ARIMA | G9: 0.15576663 | H9: 4.2056989 | I9: 27 | J9: =_xludf.MINIFS($G$5:$G$168,$A$5:$A$168,A9,$B$5:$B$168,B9) -> #NAME? | K9: =IF(J9=0,0,(G9-J9)/J9) -> #NAME? | L9: =K9<=Rules!$B$5 -> #NAME? | M9: -4494.561 | N9: 1.417 | O9: -4479.282 | P9: 1.58 | Q9: -4529.137 | R9: 1.38 | S9: 3 | T9: 1.417 | U9: 1.58 | V9: =T9<=Rules!$B$4 -> TRUE | W9: =AND(L9,V9) -> #NAME? | X9: 2 | Y9: TRUE | Z9: joint_acceptable | AA9: Both thresholds met; simplest eligible AR/MA structure selected.
A10: 4 | B10: 10 | C10: arima_011 | D10: (0, 1, 1) | E10: (0, 0, 0, 0) | F10: ARIMA | G10: 0.15993546 | H10: 4.3182574 | I10: 27 | J10: =_xludf.MINIFS($G$5:$G$168,$A$5:$A$168,A10,$B$5:$B$168,B10) -> #NAME? | K10: =IF(J10=0,0,(G10-J10)/J10) -> #NAME? | L10: =K10<=Rules!$B$5 -> #NAME? | Q10: -3808.904 | R10: 0 | S10: 1 | T10: 0 | U10: 0 | V10: =T10<=Rules!$B$4 -> TRUE | W10: =AND(L10,V10) -> #NAME? | X10: 1 | Y10: TRUE | Z10: joint_acceptable | AA10: Both thresholds met; simplest eligible AR/MA structure selected.
A11: 4 | B11: 10 | C11: arima_012 | D11: (0, 1, 2) | E11: (0, 0, 0, 0) | F11: ARIMA | G11: 0.16198423 | H11: 4.3735743 | I11: 27 | J11: =_xludf.MINIFS($G$5:$G$168,$A$5:$A$168,A11,$B$5:$B$168,B11) -> #NAME? | K11: =IF(J11=0,0,(G11-J11)/J11) -> #NAME? | L11: =K11<=Rules!$B$5 -> #NAME? | M11: -3772.007 | N11: 0 | O11: -3771.119 | P11: 0 | S11: 2 | T11: 0 | U11: 0 | V11: =T11<=Rules!$B$4 -> TRUE | W11: =AND(L11,V11) -> #NAME? | X11: 2 | Y11: FALSE | Z11: not_selected | AA11: Outside the final eligible set.
A12: 5 | B12: 10 | C12: arima_400 | D12: (4, 0, 0) | E12: (0, 0, 0, 0) | F12: ARIMA | G12: 0.10166552 | H12: 2.7449691 | I12: 27 | J12: =_xludf.MINIFS($G$5:$G$168,$A$5:$A$168,A12,$B$5:$B$168,B12) -> #NAME? | K12: =IF(J12=0,0,(G12-J12)/J12) -> #NAME? | L12: =K12<=Rules!$B$5 -> #NAME? | M12: -4907.391 | N12: 35.349 | S12: 1 | T12: 35.349 | U12: 35.349 | V12: =T12<=Rules!$B$4 -> FALSE | W12: =AND(L12,V12) -> #NAME? | X12: 4 | Y12: FALSE | Z12: not_selected | AA12: Outside the final eligible set.
A13: 5 | B13: 10 | C13: arima_202 | D13: (2, 0, 2) | E13: (0, 0, 0, 0) | F13: ARIMA | G13: 0.10228087 | H13: 2.7615836 | I13: 27 | J13: =_xludf.MINIFS($G$5:$G$168,$A$5:$A$168,A13,$B$5:$B$168,B13) -> #NAME? | K13: =IF(J13=0,0,(G13-J13)/J13) -> #NAME? | L13: =K13<=Rules!$B$5 -> #NAME? | Q13: -4948.905 | R13: 0 | S13: 1 | T13: 0 | U13: 0 | V13: =T13<=Rules!$B$4 -> TRUE | W13: =AND(L13,V13) -> #NAME? | X13: 4 | Y13: FALSE | Z13: not_selected | AA13: Outside the final eligible set.
A14: 5 | B14: 10 | C14: arima_102 | D14: (1, 0, 2) | E14: (0, 0, 0, 0) | F14: ARIMA | G14: 0.10261218 | H14: 2.7705289 | I14: 27 | J14: =_xludf.MINIFS($G$5:$G$168,$A$5:$A$168,A14,$B$5:$B$168,B14) -> #NAME? | K14: =IF(J14=0,0,(G14-J14)/J14) -> #NAME? | L14: =K14<=Rules!$B$5 -> #NAME? | M14: -4942.74 | N14: 0 | O14: -4940.97 | P14: 0 | S14: 2 | T14: 0 | U14: 0 | V14: =T14<=Rules!$B$4 -> TRUE | W14: =AND(L14,V14) -> #NAME? | X14: 3 | Y14: TRUE | Z14: joint_acceptable | AA14: Both thresholds met; simplest eligible AR/MA structure selected.
A15: 5 | B15: 10 | C15: sarima_002_100_5 | D15: (0, 0, 2) | E15: (1, 0, 0, 5) | F15: SARIMA | G15: 0.12539992 | H15: 3.3857979 | I15: 27 | J15: =_xludf.MINIFS($G$5:$G$168,$A$5:$A$168,A15,$B$5:$B$168,B15) -> #NAME? | K15: =IF(J15=0,0,(G15-J15)/J15) -> #NAME? | L15: =K15<=Rules!$B$5 -> #NAME? | O15: -4836.352 | P15: 104.618 | S15: 1 | T15: 104.618 | U15: 104.618 | V15: =T15<=Rules!$B$4 -> FALSE | W15: =AND(L15,V15) -> #NAME? | X15: 3 | Y15: FALSE | Z15: not_selected | AA15: Outside the final eligible set.
A16: 5 | B16: 10 | C16: sarima_100_100_5 | D16: (1, 0, 0) | E16: (1, 0, 0, 5) | F16: SARIMA | G16: 0.17351136 | H16: 4.6848067 | I16: 27 | J16: =_xludf.MINIFS($G$5:$G$168,$A$5:$A$168,A16,$B$5:$B$168,B16) -> #NAME? | K16: =IF(J16=0,0,(G16-J16)/J16) -> #NAME? | L16: =K16<=Rules!$B$5 -> #NAME? | Q16: -4853.315 | R16: 95.59 | S16: 1 | T16: 95.59 | U16: 95.59 | V16: =T16<=Rules!$B$4 -> FALSE | W16: =AND(L16,V16) -> #NAME? | X16: 2 | Y16: FALSE | Z16: not_selected | AA16: Outside the final eligible set.
A17: 6 | B17: 10 | C17: arima_211 | D17: (2, 1, 1) | E17: (0, 0, 0, 0) | F17: ARIMA | G17: 0.12703397 | H17: 3.4299173 | I17: 27 | J17: =_xludf.MINIFS($G$5:$G$168,$A$5:$A$168,A17,$B$5:$B$168,B17) -> #NAME? | K17: =IF(J17=0,0,(G17-J17)/J17) -> #NAME? | L17: =K17<=Rules!$B$5 -> #NAME? | Q17: -6152.064 | R17: 0 | S17: 1 | T17: 0 | U17: 0 | V17: =T17<=Rules!$B$4 -> TRUE | W17: =AND(L17,V17) -> #NAME? | X17: 3 | Y17: FALSE | Z17: not_selected | AA17: Outside the final eligible set.
A18: 6 | B18: 10 | C18: sarima_011_200_5 | D18: (0, 1, 1) | E18: (2, 0, 0, 5) | F18: SARIMA | G18: 0.1271372 | H18: 3.4327044 | I18: 27 | J18: =_xludf.MINIFS($G$5:$G$168,$A$5:$A$168,A18,$B$5:$B$168,B18) -> #NAME? | K18: =IF(J18=0,0,(G18-J18)/J18) -> #NAME? | L18: =K18<=Rules!$B$5 -> #NAME? | Q18: -6150.469 | R18: 1.595 | S18: 1 | T18: 1.595 | U18: 1.595 | V18: =T18<=Rules!$B$4 -> TRUE | W18: =AND(L18,V18) -> #NAME? | X18: 3 | Y18: FALSE | Z18: not_selected | AA18: Outside the final eligible set.
A19: 6 | B19: 10 | C19: arima_011 | D19: (0, 1, 1) | E19: (0, 0, 0, 0) | F19: ARIMA | G19: 0.12748419 | H19: 3.4420732 | I19: 27 | J19: =_xludf.MINIFS($G$5:$G$168,$A$5:$A$168,A19,$B$5:$B$168,B19) -> #NAME? | K19: =IF(J19=0,0,(G19-J19)/J19) -> #NAME? | L19: =K19<=Rules!$B$5 -> #NAME? | M19: -6105.423 | N19: 0 | O19: -6094.144 | P19: 0 | S19: 2 | T19: 0 | U19: 0 | V19: =T19<=Rules!$B$4 -> TRUE | W19: =AND(L19,V19) -> #NAME? | X19: 1 | Y19: TRUE | Z19: joint_acceptable | AA19: Both thresholds met; simplest eligible AR/MA structure selected.
A20: 7 | B20: 10 | C20: arima_012 | D20: (0, 1, 2) | E20: (0, 0, 0, 0) | F20: ARIMA | G20: 0.24803441 | H20: 6.6969292 | I20: 27 | J20: =_xludf.MINIFS($G$5:$G$168,$A$5:$A$168,A20,$B$5:$B$168,B20) -> #NAME? | K20: =IF(J20=0,0,(G20-J20)/J20) -> #NAME? | L20: =K20<=Rules!$B$5 -> #NAME? | M20: -7430.791 | N20: 8.489 | S20: 1 | T20: 8.489 | U20: 8.489 | V20: =T20<=Rules!$B$4 -> FALSE | W20: =AND(L20,V20) -> #NAME? | X20: 2 | Y20: FALSE | Z20: not_selected | AA20: Outside the final eligible set.
A21: 7 | B21: 10 | C21: sarima_011_100_5 | D21: (0, 1, 1) | E21: (1, 0, 0, 5) | F21: SARIMA | G21: 0.24812304 | H21: 6.6993222 | I21: 27 | J21: =_xludf.MINIFS($G$5:$G$168,$A$5:$A$168,A21,$B$5:$B$168,B21) -> #NAME? | K21: =IF(J21=0,0,(G21-J21)/J21) -> #NAME? | L21: =K21<=Rules!$B$5 -> #NAME? | M21: -7439.28 | N21: 0 | O21: -7436.118 | P21: 0 | S21: 2 | T21: 0 | U21: 0 | V21: =T21<=Rules!$B$4 -> TRUE | W21: =AND(L21,V21) -> #NAME? | X21: 2 | Y21: FALSE | Z21: not_selected | AA21: Outside the final eligible set.
A22: 7 | B22: 10 | C22: arima_112 | D22: (1, 1, 2) | E22: (0, 0, 0, 0) | F22: ARIMA | G22: 0.24812558 | H22: 6.6993906 | I22: 27 | J22: =_xludf.MINIFS($G$5:$G$168,$A$5:$A$168,A22,$B$5:$B$168,B22) -> #NAME? | K22: =IF(J22=0,0,(G22-J22)/J22) -> #NAME? | L22: =K22<=Rules!$B$5 -> #NAME? | Q22: -7458.368 | R22: 0 | S22: 1 | T22: 0 | U22: 0 | V22: =T22<=Rules!$B$4 -> TRUE | W22: =AND(L22,V22) -> #NAME? | X22: 3 | Y22: FALSE | Z22: not_selected | AA22: Outside the final eligible set.
A23: 7 | B23: 10 | C23: arima_011 | D23: (0, 1, 1) | E23: (0, 0, 0, 0) | F23: ARIMA | G23: 0.2481418 | H23: 6.6998286 | I23: 27 | J23: =_xludf.MINIFS($G$5:$G$168,$A$5:$A$168,A23,$B$5:$B$168,B23) -> #NAME? | K23: =IF(J23=0,0,(G23-J23)/J23) -> #NAME? | L23: =K23<=Rules!$B$5 -> #NAME? | O23: -7435.07 | P23: 1.048 | S23: 1 | T23: 1.048 | U23: 1.048 | V23: =T23<=Rules!$B$4 -> TRUE | W23: =AND(L23,V23) -> #NAME? | X23: 1 | Y23: TRUE | Z23: joint_acceptable | AA23: Both thresholds met; simplest eligible AR/MA structure selected.
A24: 8 | B24: 10 | C24: arima_011 | D24: (0, 1, 1) | E24: (0, 0, 0, 0) | F24: ARIMA | G24: 0.17889177 | H24: 4.8300778 | I24: 27 | J24: =_xludf.MINIFS($G$5:$G$168,$A$5:$A$168,A24,$B$5:$B$168,B24) -> #NAME? | K24: =IF(J24=0,0,(G24-J24)/J24) -> #NAME? | L24: =K24<=Rules!$B$5 -> #NAME? | Q24: -6216.733 | R24: 0.509 | S24: 1 | T24: 0.509 | U24: 0.509 | V24: =T24<=Rules!$B$4 -> TRUE | W24: =AND(L24,V24) -> #NAME? | X24: 1 | Y24: TRUE | Z24: joint_acceptable | AA24: Both thresholds met; simplest eligible AR/MA structure selected.
A25: 8 | B25: 10 | C25: arima_111 | D25: (1, 1, 1) | E25: (0, 0, 0, 0) | F25: ARIMA | G25: 0.17892216 | H25: 4.8308984 | I25: 27 | J25: =_xludf.MINIFS($G$5:$G$168,$A$5:$A$168,A25,$B$5:$B$168,B25) -> #NAME? | K25: =IF(J25=0,0,(G25-J25)/J25) -> #NAME? | L25: =K25<=Rules!$B$5 -> #NAME? | M25: -6206.354 | N25: 0 | O25: -6205.341 | P25: 1.213 | S25: 2 | T25: 0.6065 | U25: 1.213 | V25: =T25<=Rules!$B$4 -> TRUE | W25: =AND(L25,V25) -> #NAME? | X25: 2 | Y25: FALSE | Z25: not_selected | AA25: Outside the final eligible set.
A26: 8 | B26: 10 | C26: sarima_011_001_5 | D26: (0, 1, 1) | E26: (0, 0, 1, 5) | F26: SARIMA | G26: 0.17926773 | H26: 4.8402287 | I26: 27 | J26: =_xludf.MINIFS($G$5:$G$168,$A$5:$A$168,A26,$B$5:$B$168,B26) -> #NAME? | K26: =IF(J26=0,0,(G26-J26)/J26) -> #NAME? | L26: =K26<=Rules!$B$5 -> #NAME? | Q26: -6217.242 | R26: 0 | S26: 1 | T26: 0 | U26: 0 | V26: =T26<=Rules!$B$4 -> TRUE | W26: =AND(L26,V26) -> #NAME? | X26: 2 | Y26: FALSE | Z26: not_selected | AA26: Outside the final eligible set.
A27: 8 | B27: 10 | C27: arima_113 | D27: (1, 1, 3) | E27: (0, 0, 0, 0) | F27: ARIMA | G27: 0.17960774 | H27: 4.849409 | I27: 27 | J27: =_xludf.MINIFS($G$5:$G$168,$A$5:$A$168,A27,$B$5:$B$168,B27) -> #NAME? | K27: =IF(J27=0,0,(G27-J27)/J27) -> #NAME? | L27: =K27<=Rules!$B$5 -> #NAME? | O27: -6206.554 | P27: 0 | S27: 1 | T27: 0 | U27: 0 | V27: =T27<=Rules!$B$4 -> TRUE | W27: =AND(L27,V27) -> #NAME? | X27: 4 | Y27: FALSE | Z27: not_selected | AA27: Outside the final eligible set.
A28: 9 | B28: 10 | C28: arima_211 | D28: (2, 1, 1) | E28: (0, 0, 0, 0) | F28: ARIMA | G28: 0.17985229 | H28: 4.8560118 | I28: 27 | J28: =_xludf.MINIFS($G$5:$G$168,$A$5:$A$168,A28,$B$5:$B$168,B28) -> #NAME? | K28: =IF(J28=0,0,(G28-J28)/J28) -> #NAME? | L28: =K28<=Rules!$B$5 -> #NAME? | O28: -5828.825 | P28: 0 | S28: 1 | T28: 0 | U28: 0 | V28: =T28<=Rules!$B$4 -> TRUE | W28: =AND(L28,V28) -> #NAME? | X28: 3 | Y28: TRUE | Z28: joint_acceptable | AA28: Both thresholds met; simplest eligible AR/MA structure selected.
A29: 9 | B29: 10 | C29: arima_311 | D29: (3, 1, 1) | E29: (0, 0, 0, 0) | F29: ARIMA | G29: 0.17995654 | H29: 4.8588267 | I29: 27 | J29: =_xludf.MINIFS($G$5:$G$168,$A$5:$A$168,A29,$B$5:$B$168,B29) -> #NAME? | K29: =IF(J29=0,0,(G29-J29)/J29) -> #NAME? | L29: =K29<=Rules!$B$5 -> #NAME? | M29: -5830.952 | N29: 0 | S29: 1 | T29: 0 | U29: 0 | V29: =T29<=Rules!$B$4 -> TRUE | W29: =AND(L29,V29) -> #NAME? | X29: 4 | Y29: FALSE | Z29: not_selected | AA29: Outside the final eligible set.
A30: 9 | B30: 10 | C30: arima_013 | D30: (0, 1, 3) | E30: (0, 0, 0, 0) | F30: ARIMA | G30: 0.18006532 | H30: 4.8617636 | I30: 27 | J30: =_xludf.MINIFS($G$5:$G$168,$A$5:$A$168,A30,$B$5:$B$168,B30) -> #NAME? | K30: =IF(J30=0,0,(G30-J30)/J30) -> #NAME? | L30: =K30<=Rules!$B$5 -> #NAME? | Q30: -5834.714 | R30: 0 | S30: 1 | T30: 0 | U30: 0 | V30: =T30<=Rules!$B$4 -> TRUE | W30: =AND(L30,V30) -> #NAME? | X30: 3 | Y30: FALSE | Z30: not_selected | AA30: Outside the final eligible set.
A31: 9 | B31: 10 | C31: arima_011 | D31: (0, 1, 1) | E31: (0, 0, 0, 0) | F31: ARIMA | G31: 0.18045638 | H31: 4.8723222 | I31: 27 | J31: =_xludf.MINIFS($G$5:$G$168,$A$5:$A$168,A31,$B$5:$B$168,B31) -> #NAME? | K31: =IF(J31=0,0,(G31-J31)/J31) -> #NAME? | L31: =K31<=Rules!$B$5 -> #NAME? | O31: -5821.445 | P31: 7.38 | S31: 1 | T31: 7.38 | U31: 7.38 | V31: =T31<=Rules!$B$4 -> FALSE | W31: =AND(L31,V31) -> #NAME? | X31: 1 | Y31: FALSE | Z31: not_selected | AA31: Outside the final eligible set.
A32: 10 | B32: 10 | C32: arima_012 | D32: (0, 1, 2) | E32: (0, 0, 0, 0) | F32: ARIMA | G32: 0.11002943 | H32: 2.9707945 | I32: 27 | J32: =_xludf.MINIFS($G$5:$G$168,$A$5:$A$168,A32,$B$5:$B$168,B32) -> #NAME? | K32: =IF(J32=0,0,(G32-J32)/J32) -> #NAME? | L32: =K32<=Rules!$B$5 -> #NAME? | M32: -4245.561 | N32: 0 | O32: -4241.258 | P32: 0.129 | Q32: -4258.77 | R32: 0 | S32: 3 | T32: 0 | U32: 0.129 | V32: =T32<=Rules!$B$4 -> TRUE | W32: =AND(L32,V32) -> #NAME? | X32: 2 | Y32: TRUE | Z32: joint_acceptable | AA32: Both thresholds met; simplest eligible AR/MA structure selected.
A33: 10 | B33: 10 | C33: sarima_012_002_5 | D33: (0, 1, 2) | E33: (0, 0, 2, 5) | F33: SARIMA | G33: 0.11016819 | H33: 2.9745412 | I33: 27 | J33: =_xludf.MINIFS($G$5:$G$168,$A$5:$A$168,A33,$B$5:$B$168,B33) -> #NAME? | K33: =IF(J33=0,0,(G33-J33)/J33) -> #NAME? | L33: =K33<=Rules!$B$5 -> #NAME? | O33: -4241.387 | P33: 0 | S33: 1 | T33: 0 | U33: 0 | V33: =T33<=Rules!$B$4 -> TRUE | W33: =AND(L33,V33) -> #NAME? | X33: 4 | Y33: FALSE | Z33: not_selected | AA33: Outside the final eligible set.
A34: 11 | B34: 10 | C34: sarima_112_001_5 | D34: (1, 1, 2) | E34: (0, 0, 1, 5) | F34: SARIMA | G34: 0.40762161 | H34: 11.005783 | I34: 27 | J34: =_xludf.MINIFS($G$5:$G$168,$A$5:$A$168,A34,$B$5:$B$168,B34) -> #NAME? | K34: =IF(J34=0,0,(G34-J34)/J34) -> #NAME? | L34: =K34<=Rules!$B$5 -> #NAME? | M34: -4972.129 | N34: 0 | S34: 1 | T34: 0 | U34: 0 | V34: =T34<=Rules!$B$4 -> TRUE | W34: =AND(L34,V34) -> #NAME? | X34: 4 | Y34: TRUE | Z34: joint_acceptable | AA34: Both thresholds met; simplest eligible AR/MA structure selected.
A35: 11 | B35: 10 | C35: sarima_111_001_5 | D35: (1, 1, 1) | E35: (0, 0, 1, 5) | F35: SARIMA | G35: 0.4129155 | H35: 11.148718 | I35: 27 | J35: =_xludf.MINIFS($G$5:$G$168,$A$5:$A$168,A35,$B$5:$B$168,B35) -> #NAME? | K35: =IF(J35=0,0,(G35-J35)/J35) -> #NAME? | L35: =K35<=Rules!$B$5 -> #NAME? | Q35: -4971.144 | R35: 0 | S35: 1 | T35: 0 | U35: 0 | V35: =T35<=Rules!$B$4 -> TRUE | W35: =AND(L35,V35) -> #NAME? | X35: 3 | Y35: FALSE | Z35: not_selected | AA35: Outside the final eligible set.
A36: 11 | B36: 10 | C36: arima_111 | D36: (1, 1, 1) | E36: (0, 0, 0, 0) | F36: ARIMA | G36: 0.41400676 | H36: 11.178183 | I36: 27 | J36: =_xludf.MINIFS($G$5:$G$168,$A$5:$A$168,A36,$B$5:$B$168,B36) -> #NAME? | K36: =IF(J36=0,0,(G36-J36)/J36) -> #NAME? | L36: =K36<=Rules!$B$5 -> #NAME? | M36: -4965.865 | N36: 6.264 | O36: -4964.025 | P36: 6.122 | Q36: -4968.185 | R36: 2.959 | S36: 3 | T36: 6.122 | U36: 6.264 | V36: =T36<=Rules!$B$4 -> FALSE | W36: =AND(L36,V36) -> #NAME? | X36: 2 | Y36: FALSE | Z36: not_selected | AA36: Outside the final eligible set.
A37: 11 | B37: 10 | C37: sarima_112_100_5 | D37: (1, 1, 2) | E37: (1, 0, 0, 5) | F37: SARIMA | G37: 0.42992035 | H37: 11.60785 | I37: 27 | J37: =_xludf.MINIFS($G$5:$G$168,$A$5:$A$168,A37,$B$5:$B$168,B37) -> #NAME? | K37: =IF(J37=0,0,(G37-J37)/J37) -> #NAME? | L37: =K37<=Rules!$B$5 -> #NAME? | O37: -4970.147 | P37: 0 | S37: 1 | T37: 0 | U37: 0 | V37: =T37<=Rules!$B$4 -> TRUE | W37: =AND(L37,V37) -> #NAME? | X37: 4 | Y37: FALSE | Z37: not_selected | AA37: Outside the final eligible set.
A38: 12 | B38: 10 | C38: arima_500 | D38: (5, 0, 0) | E38: (0, 0, 0, 0) | F38: ARIMA | G38: 1.0783377 | H38: 29.115117 | I38: 27 | J38: =_xludf.MINIFS($G$5:$G$168,$A$5:$A$168,A38,$B$5:$B$168,B38) -> #NAME? | K38: =IF(J38=0,0,(G38-J38)/J38) -> #NAME? | L38: =K38<=Rules!$B$5 -> #NAME? | M38: -7089.26 | N38: 0 | O38: -7082.121 | P38: 0 | Q38: -7113.162 | R38: 6.493 | S38: 3 | T38: 0 | U38: 6.493 | V38: =T38<=Rules!$B$4 -> TRUE | W38: =AND(L38,V38) -> #NAME? | X38: 5 | Y38: TRUE | Z38: joint_acceptable | AA38: Both thresholds met; simplest eligible AR/MA structure selected.
A39: 12 | B39: 10 | C39: arima_400 | D39: (4, 0, 0) | E39: (0, 0, 0, 0) | F39: ARIMA | G39: 1.0953152 | H39: 29.57351 | I39: 27 | J39: =_xludf.MINIFS($G$5:$G$168,$A$5:$A$168,A39,$B$5:$B$168,B39) -> #NAME? | K39: =IF(J39=0,0,(G39-J39)/J39) -> #NAME? | L39: =K39<=Rules!$B$5 -> #NAME? | M39: -7087.993 | N39: 1.267 | O39: -7081.274 | P39: 0.847 | S39: 2 | T39: 1.057 | U39: 1.267 | V39: =T39<=Rules!$B$4 -> TRUE | W39: =AND(L39,V39) -> #NAME? | X39: 4 | Y39: FALSE | Z39: not_selected | AA39: Outside the final eligible set.
A40: 12 | B40: 10 | C40: arima_201 | D40: (2, 0, 1) | E40: (0, 0, 0, 0) | F40: ARIMA | G40: 1.1844398 | H40: 31.979874 | I40: 27 | J40: =_xludf.MINIFS($G$5:$G$168,$A$5:$A$168,A40,$B$5:$B$168,B40) -> #NAME? | K40: =IF(J40=0,0,(G40-J40)/J40) -> #NAME? | L40: =K40<=Rules!$B$5 -> #NAME? | Q40: -7119.655 | R40: 0 | S40: 1 | T40: 0 | U40: 0 | V40: =T40<=Rules!$B$4 -> TRUE | W40: =AND(L40,V40) -> #NAME? | X40: 3 | Y40: FALSE | Z40: not_selected | AA40: Outside the final eligible set.
A41: 13 | B41: 10 | C41: sarima_412_101_5 | D41: (4, 1, 2) | E41: (1, 0, 1, 5) | F41: SARIMA | G41: 1.8300485 | H41: 49.411311 | I41: 27 | J41: =_xludf.MINIFS($G$5:$G$168,$A$5:$A$168,A41,$B$5:$B$168,B41) -> #NAME? | K41: =IF(J41=0,0,(G41-J41)/J41) -> #NAME? | L41: =K41<=Rules!$B$5 -> #NAME? | M41: -2477.266 | N41: 0 | S41: 1 | T41: 0 | U41: 0 | V41: =T41<=Rules!$B$4 -> TRUE | W41: =AND(L41,V41) -> #NAME? | X41: 8 | Y41: FALSE | Z41: not_selected | AA41: Outside the final eligible set.
...

Sheet Rules
A1: Model selection rules and assumptions | B1: Model selection rules and assumptions | C1: Model selection rules and assumptions | D1: Model selection rules and assumptions
A3: Parameter | B3: Applied value | C3: Interpretation | D3: Role in decision
A4: AICc delta limit | B4: 2 | C4: ΔAICc ≤ 2 is treated as supported / practically tied. | D4: Candidate-level median within-method ΔAICc must be within this limit.
A5: Relative sMAPE tie limit | B5: 0.01 | C5: A candidate within 1% of the lowest mean sMAPE is practically tied. | D5: Defines the sMAPE-competitive shortlist.
A7: Step | B7: Rule | C7: Why | D7: Output
A8: 1 | B8: Compare AICc only inside the same interpolation method. | C8: Raw AICc levels from linear, pchip, and spline use different fitted series and are not directly comparable. | D8: Within-method ΔAICc
A9: 2 | B9: Shortlist candidates within the relative sMAPE limit. | C9: sMAPE is the project forecast metric and is evaluated on the common CV design. | D9: sMAPE acceptable
A10: 3 | B10: Require median within-method ΔAICc within the AICc limit. | C10: This retains candidates with reasonable likelihood support. | D10: Joint acceptable
A11: 4 | B11: Among jointly acceptable candidates, choose minimum p+q+P+Q. | C11: AR/MA coefficient count is the tie-break measure of model simplicity. | D11: Selected configuration
A12: 5 | B12: If no joint candidate exists, choose lowest sMAPE and flag it. | C12: A complete configuration is still produced, but the trade-off remains visible. | D12: Fallback status
A14: Important limitation
A15: The sMAPE file contains means and fold counts but no fold-level dispersion; therefore the 1% rule is a practical tolerance, not a statistical significance test.
A16: The selected configuration uses the SARIMAX engine for all candidates; ordinary ARIMA uses seasonal_order=(0, 0, 0, 0).

Sheet AICC_Evidence
A1: Candidate-level AICc evidence | B1: Candidate-level AICc evidence | C1: Candidate-level AICc evidence | D1: Candidate-level AICc evidence | E1: Candidate-level AICc evidence | F1: Candidate-level AICc evidence | G1: Candidate-level AICc evidence | H1: Candidate-level AICc evidence | I1: Candidate-level AICc evidence | J1: Candidate-level AICc evidence
A2: Each ΔAICc is calculated only against candidates fitted with the same material and interpolation method.
A4: material | B4: imputation_method | C4: source_run | D4: order | E4: seasonal_order | F4: model_type | G4: aicc | H4: method_best_aicc | I4: delta_from_method_best | J4: aicc_support
A5: 1 | B5: linear | C5: seasonal_auto | D5: (1, 1, 2) | E5: (1, 0, 0, 5) | F5: SARIMA | G5: -3844.78 | H5: =_xludf.MINIFS($G$5:$G$68,$A$5:$A$68,A5,$B$5:$B$68,B5) -> #NAME? | I5: =G5-H5 -> #NAME? | J5: =IF(I5<=Rules!$B$4,"supported","weaker") -> #NAME?
A6: 1 | B6: linear | C6: nonseasonal_auto | D6: (1, 1, 2) | E6: (0, 0, 0, 0) | F6: ARIMA | G6: -3842.27 | H6: =_xludf.MINIFS($G$5:$G$68,$A$5:$A$68,A6,$B$5:$B$68,B6) -> #NAME? | I6: =G6-H6 -> #NAME? | J6: =IF(I6<=Rules!$B$4,"supported","weaker") -> #NAME?
A7: 1 | B7: pchip | C7: seasonal_auto | D7: (1, 1, 2) | E7: (1, 0, 0, 5) | F7: SARIMA | G7: -3836.968 | H7: =_xludf.MINIFS($G$5:$G$68,$A$5:$A$68,A7,$B$5:$B$68,B7) -> #NAME? | I7: =G7-H7 -> #NAME? | J7: =IF(I7<=Rules!$B$4,"supported","weaker") -> #NAME?
A8: 1 | B8: pchip | C8: nonseasonal_auto | D8: (1, 1, 2) | E8: (0, 0, 0, 0) | F8: ARIMA | G8: -3836.025 | H8: =_xludf.MINIFS($G$5:$G$68,$A$5:$A$68,A8,$B$5:$B$68,B8) -> #NAME? | I8: =G8-H8 -> #NAME? | J8: =IF(I8<=Rules!$B$4,"supported","weaker") -> #NAME?
A9: 1 | B9: spline | C9: seasonal_auto | D9: (1, 1, 2) | E9: (1, 0, 0, 5) | F9: SARIMA | G9: -3858.851 | H9: =_xludf.MINIFS($G$5:$G$68,$A$5:$A$68,A9,$B$5:$B$68,B9) -> #NAME? | I9: =G9-H9 -> #NAME? | J9: =IF(I9<=Rules!$B$4,"supported","weaker") -> #NAME?
A10: 1 | B10: spline | C10: nonseasonal_auto | D10: (1, 1, 2) | E10: (0, 0, 0, 0) | F10: ARIMA | G10: -3857.196 | H10: =_xludf.MINIFS($G$5:$G$68,$A$5:$A$68,A10,$B$5:$B$68,B10) -> #NAME? | I10: =G10-H10 -> #NAME? | J10: =IF(I10<=Rules!$B$4,"supported","weaker") -> #NAME?
A11: 2 | B11: linear | C11: nonseasonal_auto | D11: (1, 1, 1) | E11: (0, 0, 0, 0) | F11: ARIMA | G11: -4426.001 | H11: =_xludf.MINIFS($G$5:$G$68,$A$5:$A$68,A11,$B$5:$B$68,B11) -> #NAME? | I11: =G11-H11 -> #NAME? | J11: =IF(I11<=Rules!$B$4,"supported","weaker") -> #NAME?
A12: 2 | B12: pchip | C12: nonseasonal_auto | D12: (1, 1, 1) | E12: (0, 0, 0, 0) | F12: ARIMA | G12: -4425.005 | H12: =_xludf.MINIFS($G$5:$G$68,$A$5:$A$68,A12,$B$5:$B$68,B12) -> #NAME? | I12: =G12-H12 -> #NAME? | J12: =IF(I12<=Rules!$B$4,"supported","weaker") -> #NAME?
A13: 2 | B13: spline | C13: nonseasonal_auto | D13: (1, 1, 1) | E13: (0, 0, 0, 0) | F13: ARIMA | G13: -4432.271 | H13: =_xludf.MINIFS($G$5:$G$68,$A$5:$A$68,A13,$B$5:$B$68,B13) -> #NAME? | I13: =G13-H13 -> #NAME? | J13: =IF(I13<=Rules!$B$4,"supported","weaker") -> #NAME?
A14: 3 | B14: linear | C14: seasonal_auto | D14: (1, 1, 1) | E14: (0, 0, 2, 5) | F14: SARIMA | G14: -4495.978 | H14: =_xludf.MINIFS($G$5:$G$68,$A$5:$A$68,A14,$B$5:$B$68,B14) -> #NAME? | I14: =G14-H14 -> #NAME? | J14: =IF(I14<=Rules!$B$4,"supported","weaker") -> #NAME?
A15: 3 | B15: linear | C15: nonseasonal_auto | D15: (1, 1, 1) | E15: (0, 0, 0, 0) | F15: ARIMA | G15: -4494.561 | H15: =_xludf.MINIFS($G$5:$G$68,$A$5:$A$68,A15,$B$5:$B$68,B15) -> #NAME? | I15: =G15-H15 -> #NAME? | J15: =IF(I15<=Rules!$B$4,"supported","weaker") -> #NAME?
A16: 3 | B16: pchip | C16: seasonal_auto | D16: (1, 1, 1) | E16: (0, 0, 2, 5) | F16: SARIMA | G16: -4480.862 | H16: =_xludf.MINIFS($G$5:$G$68,$A$5:$A$68,A16,$B$5:$B$68,B16) -> #NAME? | I16: =G16-H16 -> #NAME? | J16: =IF(I16<=Rules!$B$4,"supported","weaker") -> #NAME?
... A68: 13 | B68: spline | C68: nonseasonal_auto | D68: (4, 1, 1) | E68: (0, 0, 0, 0) | F68: ARIMA | G68: -2491.09 | H68: =_xludf.MINIFS($G$5:$G$68,$A$5:$A$68,A68,$B$5:$B$68,B68) -> #NAME? | I68: =G68-H68 -> #NAME? | J68: =IF(I68<=Rules!$B$4,"supported","weaker") -> #NAME?

Sheet Source_AICC
A1: material | B1: imputation_method | C1: arima_order | D1: sarima_order | E1: sarima_seasonal_order | F1: arima_aicc | G1: sarima_aicc | H1: delta_aicc | I1: aicc_result | J1: seasonal_result
A2: 1 | B2: linear | C2: (1, 1, 2) | D2: (1, 1, 2) | E2: (1, 0, 0, 5) | F2: -3842.27 | G2: -3844.78 | H2: -2.51 | I2: SARIMA lower | J2: Seasonal terms selected
A3: 1 | B3: pchip | C3: (1, 1, 2) | D3: (1, 1, 2) | E3: (1, 0, 0, 5) | F3: -3836.025 | G3: -3836.968 | H3: -0.943 | I3: SARIMA lower | J3: Seasonal terms selected
A4: 1 | B4: spline | C4: (1, 1, 2) | D4: (1, 1, 2) | E4: (1, 0, 0, 5) | F4: -3857.196 | G4: -3858.851 | H4: -1.655 | I4: SARIMA lower | J4: Seasonal terms selected
A5: 2 | B5: linear | C5: (1, 1, 1) | D5: (1, 1, 1) | E5: (0, 0, 0, 5) | F5: -4426.001 | G5: -4426.001 | H5: 0.0 | I5: Tie | J5: No seasonal terms
A6: 2 | B6: pchip | C6: (1, 1, 1) | D6: (1, 1, 1) | E6: (0, 0, 0, 5) | F6: -4425.005 | G6: -4425.005 | H6: 0.0 | I6: Tie | J6: No seasonal terms
A7: 2 | B7: spline | C7: (1, 1, 1) | D7: (1, 1, 1) | E7: (0, 0, 0, 5) | F7: -4432.271 | G7: -4432.271 | H7: 0.0 | I7: Tie | J7: No seasonal terms
A8: 3 | B8: linear | C8: (1, 1, 1) | D8: (1, 1, 1) | E8: (0, 0, 2, 5) | F8: -4494.561 | G8: -4495.978 | H8: -1.417 | I8: SARIMA lower | J8: Seasonal terms selected
A9: 3 | B9: pchip | C9: (1, 1, 1) | D9: (1, 1, 1) | E9: (0, 0, 2, 5) | F9: -4479.282 | G9: -4480.862 | H9: -1.58 | I9: SARIMA lower | J9: Seasonal terms selected
A10: 3 | B10: spline | C10: (1, 1, 1) | D10: (1, 1, 1) | E10: (0, 0, 2, 5) | F10: -4529.137 | G10: -4530.517 | H10: -1.38 | I10: SARIMA lower | J10: Seasonal terms selected
A11: 4 | B11: linear | C11: (0, 1, 2) | D11: (0, 1, 2) | E11: (0, 0, 0, 5) | F11: -3772.007 | G11: -3772.007 | H11: 0.0 | I11: Tie | J11: No seasonal terms
A12: 4 | B12: pchip | C12: (0, 1, 2) | D12: (0, 1, 2) | E12: (0, 0, 0, 5) | F12: -3771.119 | G12: -3771.119 | H12: 0.0 | I12: Tie | J12: No seasonal terms
... A40: 13 | B40: spline | C40: (4, 1, 1) | D40: (3, 1, 2) | E40: (1, 0, 1, 5) | F40: -2491.09 | G40: -2495.423 | H40: -4.333 | I40: SARIMA lower | J40: Seasonal terms selected

Sheet Source_sMAPE
A1: material | B1: horizon | C1: candidate | D1: order | E1: seasonal_order | F1: mean_smape | G1: sum_smape | H1: number_of_folds
A2: 1 | B2: 10 | C2: arima_112 | D2: (1, 1, 2) | E2: (0, 0, 0, 0) | F2: 0.10521148696882493 | G2: 2.8407101481582733 | H2: 27
A3: 1 | B3: 10 | C3: sarima_112_100_5 | D3: (1, 1, 2) | E3: (1, 0, 0, 5) | F3: 0.10202196839480403 | G3: 2.7545931466597087 | H3: 27
A4: 2 | B4: 10 | C4: arima_111 | D4: (1, 1, 1) | E4: (0, 0, 0, 0) | F4: 0.1361064845120819 | G4: 3.6748750818262113 | H4: 27
A5: 3 | B5: 10 | C5: arima_111 | D5: (1, 1, 1) | E5: (0, 0, 0, 0) | F5: 0.1557666274815043 | G5: 4.205698942000616 | H5: 27
A6: 3 | B6: 10 | C6: sarima_111_002_5 | D6: (1, 1, 1) | E6: (0, 0, 2, 5) | F6: 0.15529330892651383 | G6: 4.192919341015873 | H6: 27
A7: 4 | B7: 10 | C7: arima_011 | D7: (0, 1, 1) | E7: (0, 0, 0, 0) | F7: 0.15993545953300364 | G7: 4.318257407391099 | H7: 27
A8: 4 | B8: 10 | C8: arima_012 | D8: (0, 1, 2) | E8: (0, 0, 0, 0) | F8: 0.16198423221149152 | G8: 4.3735742697102715 | H8: 27
A9: 5 | B9: 10 | C9: arima_102 | D9: (1, 0, 2) | E9: (0, 0, 0, 0) | F9: 0.10261218243624201 | G9: 2.7705289257785344 | H9: 27
A10: 5 | B10: 10 | C10: arima_202 | D10: (2, 0, 2) | E10: (0, 0, 0, 0) | F10: 0.10228087314707242 | G10: 2.761583574970955 | H10: 27
A11: 5 | B11: 10 | C11: arima_400 | D11: (4, 0, 0) | E11: (0, 0, 0, 0) | F11: 0.1016655219908528 | G11: 2.7449690937530256 | H11: 27
A12: 5 | B12: 10 | C12: sarima_002_100_5 | D12: (0, 0, 2) | E12: (1, 0, 0, 5) | F12: 0.1253999214334 | G12: 3.3857978787018004 | H12: 27
... A165: 13 | B165: 132 | C165: sarima_412_101_5 | D165: (4, 1, 2) | E165: (1, 0, 1, 5) | F165: 1.83430455145493 | G165: 3.66860910290986 | H165: 2

Sheet Config_Python
A1: Copy-ready FORECASTING_CONFIG | B1: Copy-ready FORECASTING_CONFIG
A2: All entries call the same SARIMAX-backed forecast function; nonseasonal candidates use seasonal_order=(0, 0, 0, 0).
A4: line | B4: python_code
A5: 1 | B5: FORECASTING_CONFIG = {
A6: 2 | B6: 10: {
A7: 3 | B7: "1": {"model": "arima", "params": {"order": (1, 1, 2), "seasonal_order": (1, 0, 0, 5)}},
A8: 4 | B8: "2": {"model": "arima", "params": {"order": (1, 1, 1), "seasonal_order": (0, 0, 0, 0)}},
A9: 5 | B9: "3": {"model": "arima", "params": {"order": (1, 1, 1), "seasonal_order": (0, 0, 0, 0)}},
A10: 6 | B10: "4": {"model": "arima", "params": {"order": (0, 1, 1), "seasonal_order": (0, 0, 0, 0)}},
A11: 7 | B11: "5": {"model": "arima", "params": {"order": (1, 0, 2), "seasonal_order": (0, 0, 0, 0)}},
A12: 8 | B12: "6": {"model": "arima", "params": {"order": (0, 1, 1), "seasonal_order": (0, 0, 0, 0)}},
A13: 9 | B13: "7": {"model": "arima", "params": {"order": (0, 1, 1), "seasonal_order": (0, 0, 0, 0)}},
A14: 10 | B14: "8": {"model": "arima", "params": {"order": (0, 1, 1), "seasonal_order": (0, 0, 0, 0)}},
A15: 11 | B15: "9": {"model": "arima", "params": {"order": (2, 1, 1), "seasonal_order": (0, 0, 0, 0)}},
A16: 12 | B16: "10": {"model": "arima", "params": {"order": (0, 1, 2), "seasonal_order": (0, 0, 0, 0)}},
... A66: 62 | B66: }
